using FluentAssertions;
using Tests.Fixtures;
using XResults;
using XResults.Exceptions;

namespace Tests;

public class ResultOfTAndTErrorTests
{
    [Fact]
    public void result_succeeds()
    {
        Result<int, CustomError> result = Result.Ok(123);

        result.IsSuccess.Should().Be(true);
        result.IsFailure.Should().Be(false);
        result.Error.Should().Be(null);
        result.Value.Should().Be(123);
    }

    [Fact]
    public void result_fails()
    {
        Result<int, CustomError> result = Result.Fail(new CustomError());

        result.IsSuccess.Should().Be(false);
        result.IsFailure.Should().Be(true);
        result.Error.Should().BeOfType<CustomError>();
        Assert.Throws<OperationFailedException>(() => result.Value);
    }

    [Fact]
    public void automatically_convertes_returned_type()
    {
        Result<int, CustomError> result = 123;

        result.IsSuccess.Should().Be(true);
        result.IsFailure.Should().Be(false);
        result.Value.Should().Be(123);
        result.Error.Should().Be(null);
    }

    [Fact]
    public void result_fails_when_only_returning_the_error()
    {
        Result<int, CustomError> result = new CustomError();

        result.IsSuccess.Should().Be(false);
        result.IsFailure.Should().Be(true);
        result.Error.Should().BeOfType<CustomError>();
        Assert.Throws<OperationFailedException>(() => result.Value);
    }

    [Fact]
    public void create_successful_result()
    {
        Result<int, CustomError> result = Result<int, CustomError>.Create(true, 123);

        result.IsSuccess.Should().Be(true);
        result.IsFailure.Should().Be(false);
        result.Value.Should().Be(123);
        result.Error.Should().Be(null);
    }

    [Fact]
    public void create_failed_result()
    {
        Result<int, CustomError> result = Result<int, CustomError>.Create(
            false,
            0,
            new CustomError()
        );

        result.IsSuccess.Should().Be(false);
        result.IsFailure.Should().Be(true);
        Assert.Throws<OperationFailedException>(() => result.Value);
        result.Error.Should().BeOfType<CustomError>();
    }

    [Fact]
    public void throw_when_creating_successful_result_with_error()
    {
        Assert.Throws<Exception>(() => Result<int, CustomError>.Create(true, 0, new CustomError()));
    }

    [Fact]
    public void throw_when_creating_failed_result_with_value()
    {
        Assert.Throws<Exception>(
            () => Result<int, CustomError>.Create(false, 123, new CustomError())
        );
    }
}
